Workbook

Sheet Analysis
A1: Analysis
A4: A. Translation per task (0–2 points; 2 = both views correct; tests exploratory)
D5: Fully solved (2 points) | H5: Mean points (0–2) | L5: Test session 1 | P5: Test session 2 (post-test)
A6: Task | B6: Level | C6: Given view | D6: S1 Tool condition | E6: S1 Paper condition | F6: S2 Tool condition | G6: S2 Paper condition | H6: S1 Tool condition | I6: S1 Paper condition | J6: S2 Tool condition | K6: S2 Paper condition | L6: U | M6: p | N6: p (Holm) | O6: r | P6: U | Q6: p | R6: p (Holm) | S6: r
A7: T1 | B7: =IF(Tasks!$G$2="No","",Tasks!E2&"") -> Gate | C7: =IF(Tasks!$G$2="No","",Tasks!D2&"") -> Model | D7: =IF(Tasks!$G$2="No","",COUNTIFS(Scores!$B$5:$B$44,1,Scores!$C$5:$C$44,"Tool condition",Scores!E$5:E$44,2)) -> 10 | E7: =IF(Tasks!$G$2="No","",COUNTIFS(Scores!$B$5:$B$44,1,Scores!$C$5:$C$44,"Paper condition",Scores!E$5:E$44,2)) -> 6 | F7: =IF(Tasks!$G$2="No","",COUNTIFS(Scores!$B$5:$B$44,2,Scores!$C$5:$C$44,"Tool condition",Scores!E$5:E$44,2)) -> 7 | G7: =IF(Tasks!$G$2="No","",COUNTIFS(Scores!$B$5:$B$44,2,Scores!$C$5:$C$44,"Paper condition",Scores!E$5:E$44,2)) -> 5 | H7: =IF(Tasks!$G$2="No","",IFERROR(AVERAGEIFS(Scores!E$5:E$44,Scores!$B$5:$B$44,1,Scores!$C$5:$C$44,"Tool condition"),"")) -> 2 | I7: =IF(Tasks!$G$2="No","",IFERROR(AVERAGEIFS(Scores!E$5:E$44,Scores!$B$5:$B$44,1,Scores!$C$5:$C$44,"Paper condition"),"")) -> 1.5 | J7: =IF(Tasks!$G$2="No","",IFERROR(AVERAGEIFS(Scores!E$5:E$44,Scores!$B$5:$B$44,2,Scores!$C$5:$C$44,"Tool condition"),"")) -> 1.7 | K7: =IF(Tasks!$G$2="No","",IFERROR(AVERAGEIFS(Scores!E$5:E$44,Scores!$B$5:$B$44,2,Scores!$C$5:$C$44,"Paper condition"),"")) -> 1.5 | L7: =IF(Tasks!$G$2="No","",IF(OR(COUNTIFS(Scores!$B$5:$B$44,1,Scores!$C$5:$C$44,"Tool condition",Scores!E$5:E$44,">=0")=0,COUNTIFS(Scores!$B$5:$B$44,1,Scores!$C$5:$C$44,"Paper condition",Scores!E$5:E$44,">=0")=0),"",SUM(Helper!B$5:B$44))) -> 70 | M7: =IF(L7="","",IF(SQRT(COUNTIFS(Scores!$B$5:$B$44,1,Scores!$C$5:$C$44,"Tool condition",Scores!E$5:E$44,">=0")*COUNTIFS(Scores!$B$5:$B$44,1,Scores!$C$5:$C$44,"Paper condition",Scores!E$5:E$44,">=0")/12*(((COUNTIFS(Scores!$B$5:$B$44,1,Scores!$C$5:$C$44,"Tool condition",Scores!E$5:E$44,">=0")+COUNTIFS(Scores!$B$5:$B$44,1,Scores!$C$5:$C$44,"Paper condition",Scores!E$5:E$44,">=0"))+1)-SUM(Helper!C$5:C$44)/((COUNTIFS(Scores!$B$5:$B$44,1,Scores!$C$5:$C$44,"Tool condition",Scores!E$5:E$44,">=0")+COUNTIFS(Scores!$B$5:$B$44,1,Scores!$C$5:$C$44,"Paper condition",Scores!E$5:E$44,">=0"))*((COUNTIFS(Scores!$B$5:$B$44,1,Scores!$C$5:$C$44,"Tool condition",Scores!E$5:E$44,">=0")+COUNTIFS(Scores!$B$5:$B$44,1,Scores!$C$5:$C$44,"Paper condition",Scores!E$5:E$44,">=0"))-1))))=0,1,MIN(1,2*(1-NORMSDIST((ABS(L7-COUNTIFS(Scores!$B$5:$B$44,1,Scores!$C$5:$C$44,"Tool condition",Scores!E$5:E$44,">=0")*COUNTIFS(Scores!$B$5:$B$44,1,Scores!$C$5:$C$44,"Paper condition",Scores!E$5:E$44,">=0")/2)-0.5)/SQRT(COUNTIFS(Scores!$B$5:$B$44,1,Scores!$C$5:$C$44,"Tool condition",Scores!E$5:E$44,">=0")*COUNTIFS(Scores!$B$5:$B$44,1,Scores!$C$5:$C$44,"Paper condition",Scores!E$5:E$44,">=0")/12*(((COUNTIFS(Scores!$B$5:$B$44,1,Scores!$C$5:$C$44,"Tool condition",Scores!E$5:E$44,">=0")+COUNTIFS(Scores!$B$5:$B$44,1,Scores!$C$5:$C$44,"Paper condition",Scores!E$5:E$44,">=0"))+1)-SUM(Helper!C$5:C$44)/((COUNTIFS(Scores!$B$5:$B$44,1,Scores!$C$5:$C$44,"Tool condition",Scores!E$5:E$44,">=0")+COUNTIFS(Scores!$B$5:$B$44,1,Scores!$C$5:$C$44,"Paper condition",Scores!E$5:E$44,">=0"))*((COUNTIFS(Scores!$B$5:$B$44,1,Scores!$C$5:$C$44,"Tool condition",Scores!E$5:E$44,">=0")+COUNTIFS(Scores!$B$5:$B$44,1,Scores!$C$5:$C$44,"Paper condition",Scores!E$5:E$44,">=0"))-1))))))))) -> 0.034423814 | N7: =IF(M7="","",INDEX(Helper!$D$100:$D$111,RANK(M7,Analysis!$M$7:$M$18,1)+COUNTIF(Analysis!$M$7:$M$18,M7)-1)) -> 0.20153808 | O7: =IF(L7="","",2*L7/(COUNTIFS(Scores!$B$5:$B$44,1,Scores!$C$5:$C$44,"Tool condition",Scores!E$5:E$44,">=0")*COUNTIFS(Scores!$B$5:$B$44,1,Scores!$C$5:$C$44,"Paper condition",Scores!E$5:E$44,">=0"))-1) -> 0.4 | P7: =IF(Tasks!$G$2="No","",IF(OR(COUNTIFS(Scores!$B$5:$B$44,2,Scores!$C$5:$C$44,"Tool condition",Scores!E$5:E$44,">=0")=0,COUNTIFS(Scores!$B$5:$B$44,2,Scores!$C$5:$C$44,"Paper condition",Scores!E$5:E$44,">=0")=0),"",SUM(Helper!D$5:D$44))) -> 60 | Q7: =IF(P7="","",IF(SQRT(COUNTIFS(Scores!$B$5:$B$44,2,Scores!$C$5:$C$44,"Tool condition",Scores!E$5:E$44,">=0")*COUNTIFS(Scores!$B$5:$B$44,2,Scores!$C$5:$C$44,"Paper condition",Scores!E$5:E$44,">=0")/12*(((COUNTIFS(Scores!$B$5:$B$44,2,Scores!$C$5:$C$44,"Tool condition",Scores!E$5:E$44,">=0")+COUNTIFS(Scores!$B$5:$B$44,2,Scores!$C$5:$C$44,"Paper condition",Scores!E$5:E$44,">=0"))+1)-SUM(Helper!E$5:E$44)/((COUNTIFS(Scores!$B$5:$B$44,2,Scores!$C$5:$C$44,"Tool condition",Scores!E$5:E$44,">=0")+COUNTIFS(Scores!$B$5:$B$44,2,Scores!$C$5:$C$44,"Paper condition",Scores!E$5:E$44,">=0"))*((COUNTIFS(Scores!$B$5:$B$44,2,Scores!$C$5:$C$44,"Tool condition",Scores!E$5:E$44,">=0")+COUNTIFS(Scores!$B$5:$B$44,2,Scores!$C$5:$C$44,"Paper condition",Scores!E$5:E$44,">=0"))-1))))=0,1,MIN(1,2*(1-NORMSDIST((ABS(P7-COUNTIFS(Scores!$B$5:$B$44,2,Scores!$C$5:$C$44,"Tool condition",Scores!E$5:E$44,">=0")*COUNTIFS(Scores!$B$5:$B$44,2,Scores!$C$5:$C$44,"Paper condition",Scores!E$5:E$44,">=0")/2)-0.5)/SQRT(COUNTIFS(Scores!$B$5:$B$44,2,Scores!$C$5:$C$44,"Tool condition",Scores!E$5:E$44,">=0")*COUNTIFS(Scores!$B$5:$B$44,2,Scores!$C$5:$C$44,"Paper condition",Scores!E$5:E$44,">=0")/12*(((COUNTIFS(Scores!$B$5:$B$44,2,Scores!$C$5:$C$44,"Tool condition",Scores!E$5:E$44,">=0")+COUNTIFS(Scores!$B$5:$B$44,2,Scores!$C$5:$C$44,"Paper condition",Scores!E$5:E$44,">=0"))+1)-SUM(Helper!E$5:E$44)/((COUNTIFS(Scores!$B$5:$B$44,2,Scores!$C$5:$C$44,"Tool condition",Scores!E$5:E$44,">=0")+COUNTIFS(Scores!$B$5:$B$44,2,Scores!$C$5:$C$44,"Paper condition",Scores!E$5:E$44,">=0"))*((COUNTIFS(Scores!$B$5:$B$44,2,Scores!$C$5:$C$44,"Tool condition",Scores!E$5:E$44,">=0")+COUNTIFS(Scores!$B$5:$B$44,2,Scores!$C$5:$C$44,"Paper condition",Scores!E$5:E$44,">=0"))-1))))))))) -> 0.39796084 | R7: =IF(Q7="","",INDEX(Helper!$H$100:$H$111,RANK(Q7,Analysis!$Q$7:$Q$18,1)+COUNTIF(Analysis!$Q$7:$Q$18,Q7)-1)) -> 1 | S7: =IF(P7="","",2*P7/(COUNTIFS(Scores!$B$5:$B$44,2,Scores!$C$5:$C$44,"Tool condition",Scores!E$5:E$44,">=0")*COUNTIFS(Scores!$B$5:$B$44,2,Scores!$C$5:$C$44,"Paper condition",Scores!E$5:E$44,">=0"))-1) -> 0.2
A8: T2 | B8: =IF(Tasks!$G$3="No","",Tasks!E3&"") -> Gate | C8: =IF(Tasks!$G$3="No","",Tasks!D3&"") -> Code | D8: =IF(Tasks!$G$3="No","",COUNTIFS(Scores!$B$5:$B$44,1,Scores!$C$5:$C$44,"Tool condition",Scores!F$5:F$44,2)) -> 10 | E8: =IF(Tasks!$G$3="No","",COUNTIFS(Scores!$B$5:$B$44,1,Scores!$C$5:$C$44,"Paper condition",Scores!F$5:F$44,2)) -> 4 | F8: =IF(Tasks!$G$3="No","",COUNTIFS(Scores!$B$5:$B$44,2,Scores!$C$5:$C$44,"Tool condition",Scores!F$5:F$44,2)) -> 7 | G8: =IF(Tasks!$G$3="No","",COUNTIFS(Scores!$B$5:$B$44,2,Scores!$C$5:$C$44,"Paper condition",Scores!F$5:F$44,2)) -> 4 | H8: =IF(Tasks!$G$3="No","",IFERROR(AVERAGEIFS(Scores!F$5:F$44,Scores!$B$5:$B$44,1,Scores!$C$5:$C$44,"Tool condition"),"")) -> 2 | I8: =IF(Tasks!$G$3="No","",IFERROR(AVERAGEIFS(Scores!F$5:F$44,Scores!$B$5:$B$44,1,Scores!$C$5:$C$44,"Paper condition"),"")) -> 1.3 | J8: =IF(Tasks!$G$3="No","",IFERROR(AVERAGEIFS(Scores!F$5:F$44,Scores!$B$5:$B$44,2,Scores!$C$5:$C$44,"Tool condition"),"")) -> 1.7 | K8: =IF(Tasks!$G$3="No","",IFERROR(AVERAGEIFS(Scores!F$5:F$44,Scores!$B$5:$B$44,2,Scores!$C$5:$C$44,"Paper condition"),"")) -> 1.3 | L8: =IF(Tasks!$G$3="No","",IF(OR(COUNTIFS(Scores!$B$5:$B$44,1,Scores!$C$5:$C$44,"Tool condition",Scores!F$5:F$44,">=0")=0,COUNTIFS(Scores!$B$5:$B$44,1,Scores!$C$5:$C$44,"Paper condition",Scores!F$5:F$44,">=0")=0),"",SUM(Helper!G$5:G$44))) -> 80 | M8: =IF(L8="","",IF(SQRT(COUNTIFS(Scores!$B$5:$B$44,1,Scores!$C$5:$C$44,"Tool condition",Scores!F$5:F$44,">=0")*COUNTIFS(Scores!$B$5:$B$44,1,Scores!$C$5:$C$44,"Paper condition",Scores!F$5:F$44,">=0")/12*(((COUNTIFS(Scores!$B$5:$B$44,1,Scores!$C$5:$C$44,"Tool condition",Scores!F$5:F$44,">=0")+COUNTIFS(Scores!$B$5:$B$44,1,Scores!$C$5:$C$44,"Paper condition",Scores!F$5:F$44,">=0"))+1)-SUM(Helper!H$5:H$44)/((COUNTIFS(Scores!$B$5:$B$44,1,Scores!$C$5:$C$44,"Tool condition",Scores!F$5:F$44,">=0")+COUNTIFS(Scores!$B$5:$B$44,1,Scores!$C$5:$C$44,"Paper condition",Scores!F$5:F$44,">=0"))*((COUNTIFS(Scores!$B$5:$B$44,1,Scores!$C$5:$C$44,"Tool condition",Scores!F$5:F$44,">=0")+COUNTIFS(Scores!$B$5:$B$44,1,Scores!$C$5:$C$44,"Paper condition",Scores!F$5:F$44,">=0"))-1))))=0,1,MIN(1,2*(1-NORMSDIST((ABS(L8-COUNTIFS(Scores!$B$5:$B$44,1,Scores!$C$5:$C$44,"Tool condition",Scores!F$5:F$44,">=0")*COUNTIFS(Scores!$B$5:$B$44,1,Scores!$C$5:$C$44,"Paper condition",Scores!F$5:F$44,">=0")/2)-0.5)/SQRT(COUNTIFS(Scores!$B$5:$B$44,1,Scores!$C$5:$C$44,"Tool condition",Scores!F$5:F$44,">=0")*COUNTIFS(Scores!$B$5:$B$44,1,Scores!$C$5:$C$44,"Paper condition",Scores!F$5:F$44,">=0")/12*(((COUNTIFS(Scores!$B$5:$B$44,1,Scores!$C$5:$C$44,"Tool condition",Scores!F$5:F$44,">=0")+COUNTIFS(Scores!$B$5:$B$44,1,Scores!$C$5:$C$44,"Paper condition",Scores!F$5:F$44,">=0"))+1)-SUM(Helper!H$5:H$44)/((COUNTIFS(Scores!$B$5:$B$44,1,Scores!$C$5:$C$44,"Tool condition",Scores!F$5:F$44,">=0")+COUNTIFS(Scores!$B$5:$B$44,1,Scores!$C$5:$C$44,"Paper condition",Scores!F$5:F$44,">=0"))*((COUNTIFS(Scores!$B$5:$B$44,1,Scores!$C$5:$C$44,"Tool condition",Scores!F$5:F$44,">=0")+COUNTIFS(Scores!$B$5:$B$44,1,Scores!$C$5:$C$44,"Paper condition",Scores!F$5:F$44,">=0"))-1))))))))) -> 0.0054143902 | N8: =IF(M8="","",INDEX(Helper!$D$100:$D$111,RANK(M8,Analysis!$M$7:$M$18,1)+COUNTIF(Analysis!$M$7:$M$18,M8)-1)) -> 0.059558292 | O8: =IF(L8="","",2*L8/(COUNTIFS(Scores!$B$5:$B$44,1,Scores!$C$5:$C$44,"Tool condition",Scores!F$5:F$44,">=0")*COUNTIFS(Scores!$B$5:$B$44,1,Scores!$C$5:$C$44,"Paper condition",Scores!F$5:F$44,">=0"))-1) -> 0.6 | P8: =IF(Tasks!$G$3="No","",IF(OR(COUNTIFS(Scores!$B$5:$B$44,2,Scores!$C$5:$C$44,"Tool condition",Scores!F$5:F$44,">=0")=0,COUNTIFS(Scores!$B$5:$B$44,2,Scores!$C$5:$C$44,"Paper condition",Scores!F$5:F$44,">=0")=0),"",SUM(Helper!I$5:I$44))) -> 66.5 | Q8: =IF(P8="","",IF(SQRT(COUNTIFS(Scores!$B$5:$B$44,2,Scores!$C$5:$C$44,"Tool condition",Scores!F$5:F$44,">=0")*COUNTIFS(Scores!$B$5:$B$44,2,Scores!$C$5:$C$44,"Paper condition",Scores!F$5:F$44,">=0")/12*(((COUNTIFS(Scores!$B$5:$B$44,2,Scores!$C$5:$C$44,"Tool condition",Scores!F$5:F$44,">=0")+COUNTIFS(Scores!$B$5:$B$44,2,Scores!$C$5:$C$44,"Paper condition",Scores!F$5:F$44,">=0"))+1)-SUM(Helper!J$5:J$44)/((COUNTIFS(Scores!$B$5:$B$44,2,Scores!$C$5:$C$44,"Tool condition",Scores!F$5:F$44,">=0")+COUNTIFS(Scores!$B$5:$B$44,2,Scores!$C$5:$C$44,"Paper condition",Scores!F$5:F$44,">=0"))*((COUNTIFS(Scores!$B$5:$B$44,2,Scores!$C$5:$C$44,"Tool condition",Scores!F$5:F$44,">=0")+COUNTIFS(Scores!$B$5:$B$44,2,Scores!$C$5:$C$44,"Paper condition",Scores!F$5:F$44,">=0"))-1))))=0,1,MIN(1,2*(1-NORMSDIST((ABS(P8-COUNTIFS(Scores!$B$5:$B$44,2,Scores!$C$5:$C$44,"Tool condition",Scores!F$5:F$44,">=0")*COUNTIFS(Scores!$B$5:$B$44,2,Scores!$C$5:$C$44,"Paper condition",Scores!F$5:F$44,">=0")/2)-0.5)/SQRT(COUNTIFS(Scores!$B$5:$B$44,2,Scores!$C$5:$C$44,"Tool condition",Scores!F$5:F$44,">=0")*COUNTIFS(Scores!$B$5:$B$44,2,Scores!$C$5:$C$44,"Paper condition",Scores!F$5:F$44,">=0")/12*(((COUNTIFS(Scores!$B$5:$B$44,2,Scores!$C$5:$C$44,"Tool condition",Scores!F$5:F$44,">=0")+COUNTIFS(Scores!$B$5:$B$44,2,Scores!$C$5:$C$44,"Paper condition",Scores!F$5:F$44,">=0"))+1)-SUM(Helper!J$5:J$44)/((COUNTIFS(Scores!$B$5:$B$44,2,Scores!$C$5:$C$44,"Tool condition",Scores!F$5:F$44,">=0")+COUNTIFS(Scores!$B$5:$B$44,2,Scores!$C$5:$C$44,"Paper condition",Scores!F$5:F$44,">=0"))*((COUNTIFS(Scores!$B$5:$B$44,2,Scores!$C$5:$C$44,"Tool condition",Scores!F$5:F$44,">=0")+COUNTIFS(Scores!$B$5:$B$44,2,Scores!$C$5:$C$44,"Paper condition",Scores!F$5:F$44,">=0"))-1))))))))) -> 0.16849347 | R8: =IF(Q8="","",INDEX(Helper!$H$100:$H$111,RANK(Q8,Analysis!$Q$7:$Q$18,1)+COUNTIF(Analysis!$Q$7:$Q$18,Q8)-1)) -> 1 | S8: =IF(P8="","",2*P8/(COUNTIFS(Scores!$B$5:$B$44,2,Scores!$C$5:$C$44,"Tool condition",Scores!F$5:F$44,">=0")*COUNTIFS(Scores!$B$5:$B$44,2,Scores!$C$5:$C$44,"Paper condition",Scores!F$5:F$44,">=0"))-1) -> 0.33
A9: T3 | B9: =IF(Tasks!$G$4="No","",Tasks!E4&"") -> Block | C9: =IF(Tasks!$G$4="No","",Tasks!D4&"") -> Model | D9: =IF(Tasks!$G$4="No","",COUNTIFS(Scores!$B$5:$B$44,1,Scores!$C$5:$C$44,"Tool condition",Scores!G$5:G$44,2)) -> 10 | E9: =IF(Tasks!$G$4="No","",COUNTIFS(Scores!$B$5:$B$44,1,Scores!$C$5:$C$44,"Paper condition",Scores!G$5:G$44,2)) -> 7 | F9: =IF(Tasks!$G$4="No","",COUNTIFS(Scores!$B$5:$B$44,2,Scores!$C$5:$C$44,"Tool condition",Scores!G$5:G$44,2)) -> 8 | G9: =IF(Tasks!$G$4="No","",COUNTIFS(Scores!$B$5:$B$44,2,Scores!$C$5:$C$44,"Paper condition",Scores!G$5:G$44,2)) -> 6 | H9: =IF(Tasks!$G$4="No","",IFERROR(AVERAGEIFS(Scores!G$5:G$44,Scores!$B$5:$B$44,1,Scores!$C$5:$C$44,"Tool condition"),"")) -> 2 | I9: =IF(Tasks!$G$4="No","",IFERROR(AVERAGEIFS(Scores!G$5:G$44,Scores!$B$5:$B$44,1,Scores!$C$5:$C$44,"Paper condition"),"")) -> 1.7 | J9: =IF(Tasks!$G$4="No","",IFERROR(AVERAGEIFS(Scores!G$5:G$44,Scores!$B$5:$B$44,2,Scores!$C$5:$C$44,"Tool condition"),"")) -> 1.8 | K9: =IF(Tasks!$G$4="No","",IFERROR(AVERAGEIFS(Scores!G$5:G$44,Scores!$B$5:$B$44,2,Scores!$C$5:$C$44,"Paper condition"),"")) -> 1.6 | L9: =IF(Tasks!$G$4="No","",IF(OR(COUNTIFS(Scores!$B$5:$B$44,1,Scores!$C$5:$C$44,"Tool condition",Scores!G$5:G$44,">=0")=0,COUNTIFS(Scores!$B$5:$B$44,1,Scores!$C$5:$C$44,"Paper condition",Scores!G$5:G$44,">=0")=0),"",SUM(Helper!L$5:L$44))) -> 65 | M9: =IF(L9="","",IF(SQRT(COUNTIFS(Scores!$B$5:$B$44,1,Scores!$C$5:$C$44,"Tool condition",Scores!G$5:G$44,">=0")*COUNTIFS(Scores!$B$5:$B$44,1,Scores!$C$5:$C$44,"Paper condition",Scores!G$5:G$44,">=0")/12*(((COUNTIFS(Scores!$B$5:$B$44,1,Scores!$C$5:$C$44,"Tool condition",Scores!G$5:G$44,">=0")+COUNTIFS(Scores!$B$5:$B$44,1,Scores!$C$5:$C$44,"Paper condition",Scores!G$5:G$44,">=0"))+1)-SUM(Helper!M$5:M$44)/((COUNTIFS(Scores!$B$5:$B$44,1,Scores!$C$5:$C$44,"Tool condition",Scores!G$5:G$44,">=0")+COUNTIFS(Scores!$B$5:$B$44,1,Scores!$C$5:$C$44,"Paper condition",Scores!G$5:G$44,">=0"))*((COUNTIFS(Scores!$B$5:$B$44,1,Scores!$C$5:$C$44,"Tool condition",Scores!G$5:G$44,">=0")+COUNTIFS(Scores!$B$5:$B$44,1,Scores!$C$5:$C$44,"Paper condition",Scores!G$5:G$44,">=0"))-1))))=0,1,MIN(1,2*(1-NORMSDIST((ABS(L9-COUNTIFS(Scores!$B$5:$B$44,1,Scores!$C$5:$C$44,"Tool condition",Scores!G$5:G$44,">=0")*COUNTIFS(Scores!$B$5:$B$44,1,Scores!$C$5:$C$44,"Paper condition",Scores!G$5:G$44,">=0")/2)-0.5)/SQRT(COUNTIFS(Scores!$B$5:$B$44,1,Scores!$C$5:$C$44,"Tool condition",Scores!G$5:G$44,">=0")*COUNTIFS(Scores!$B$5:$B$44,1,Scores!$C$5:$C$44,"Paper condition",Scores!G$5:G$44,">=0")/12*(((COUNTIFS(Scores!$B$5:$B$44,1,Scores!$C$5:$C$44,"Tool condition",Scores!G$5:G$44,">=0")+COUNTIFS(Scores!$B$5:$B$44,1,Scores!$C$5:$C$44,"Paper condition",Scores!G$5:G$44,">=0"))+1)-SUM(Helper!M$5:M$44)/((COUNTIFS(Scores!$B$5:$B$44,1,Scores!$C$5:$C$44,"Tool condition",Scores!G$5:G$44,">=0")+COUNTIFS(Scores!$B$5:$B$44,1,Scores!$C$5:$C$44,"Paper condition",Scores!G$5:G$44,">=0"))*((COUNTIFS(Scores!$B$5:$B$44,1,Scores!$C$5:$C$44,"Tool condition",Scores!G$5:G$44,">=0")+COUNTIFS(Scores!$B$5:$B$44,1,Scores!$C$5:$C$44,"Paper condition",Scores!G$5:G$44,">=0"))-1))))))))) -> 0.076715977 | N9: =IF(M9="","",INDEX(Helper!$D$100:$D$111,RANK(M9,Analysis!$M$7:$M$18,1)+COUNTIF(Analysis!$M$7:$M$18,M9)-1)) -> 0.23014793 | O9: =IF(L9="","",2*L9/(COUNTIFS(Scores!$B$5:$B$44,1,Scores!$C$5:$C$44,"Tool condition",Scores!G$5:G$44,">=0")*COUNTIFS(Scores!$B$5:$B$44,1,Scores!$C$5:$C$44,"Paper condition",Scores!G$5:G$44,">=0"))-1) -> 0.3 | P9: =IF(Tasks!$G$4="No","",IF(OR(COUNTIFS(Scores!$B$5:$B$44,2,Scores!$C$5:$C$44,"Tool condition",Scores!G$5:G$44,">=0")=0,COUNTIFS(Scores!$B$5:$B$44,2,Scores!$C$5:$C$44,"Paper condition",Scores!G$5:G$44,">=0")=0),"",SUM(Helper!N$5:N$44))) -> 60 | Q9: =IF(P9="","",IF(SQRT(COUNTIFS(Scores!$B$5:$B$44,2,Scores!$C$5:$C$44,"Tool condition",Scores!G$5:G$44,">=0")*COUNTIFS(Scores!$B$5:$B$44,2,Scores!$C$5:$C$44,"Paper condition",Scores!G$5:G$44,">=0")/12*(((COUNTIFS(Scores!$B$5:$B$44,2,Scores!$C$5:$C$44,"Tool condition",Scores!G$5:G$44,">=0")+COUNTIFS(Scores!$B$5:$B$44,2,Scores!$C$5:$C$44,"Paper condition",Scores!G$5:G$44,">=0"))+1)-SUM(Helper!O$5:O$44)/((COUNTIFS(Scores!$B$5:$B$44,2,Scores!$C$5:$C$44,"Tool condition",Scores!G$5:G$44,">=0")+COUNTIFS(Scores!$B$5:$B$44,2,Scores!$C$5:$C$44,"Paper condition",Scores!G$5:G$44,">=0"))*((COUNTIFS(Scores!$B$5:$B$44,2,Scores!$C$5:$C$44,"Tool condition",Scores!G$5:G$44,">=0")+COUNTIFS(Scores!$B$5:$B$44,2,Scores!$C$5:$C$44,"Paper condition",Scores!G$5:G$44,">=0"))-1))))=0,1,MIN(1,2*(1-NORMSDIST((ABS(P9-COUNTIFS(Scores!$B$5:$B$44,2,Scores!$C$5:$C$44,"Tool condition",Scores!G$5:G$44,">=0")*COUNTIFS(Scores!$B$5:$B$44,2,Scores!$C$5:$C$44,"Paper condition",Scores!G$5:G$44,">=0")/2)-0.5)/SQRT(COUNTIFS(Scores!$B$5:$B$44,2,Scores!$C$5:$C$44,"Tool condition",Scores!G$5:G$44,">=0")*COUNTIFS(Scores!$B$5:$B$44,2,Scores!$C$5:$C$44,"Paper condition",Scores!G$5:G$44,">=0")/12*(((COUNTIFS(Scores!$B$5:$B$44,2,Scores!$C$5:$C$44,"Tool condition",Scores!G$5:G$44,">=0")+COUNTIFS(Scores!$B$5:$B$44,2,Scores!$C$5:$C$44,"Paper condition",Scores!G$5:G$44,">=0"))+1)-SUM(Helper!O$5:O$44)/((COUNTIFS(Scores!$B$5:$B$44,2,Scores!$C$5:$C$44,"Tool condition",Scores!G$5:G$44,">=0")+COUNTIFS(Scores!$B$5:$B$44,2,Scores!$C$5:$C$44,"Paper condition",Scores!G$5:G$44,">=0"))*((COUNTIFS(Scores!$B$5:$B$44,2,Scores!$C$5:$C$44,"Tool condition",Scores!G$5:G$44,">=0")+COUNTIFS(Scores!$B$5:$B$44,2,Scores!$C$5:$C$44,"Paper condition",Scores!G$5:G$44,">=0"))-1))))))))) -> 0.3661915 | R9: =IF(Q9="","",INDEX(Helper!$H$100:$H$111,RANK(Q9,Analysis!$Q$7:$Q$18,1)+COUNTIF(Analysis!$Q$7:$Q$18,Q9)-1)) -> 1 | S9: =IF(P9="","",2*P9/(COUNTIFS(Scores!$B$5:$B$44,2,Scores!$C$5:$C$44,"Tool condition",Scores!G$5:G$44,">=0")*COUNTIFS(Scores!$B$5:$B$44,2,Scores!$C$5:$C$44,"Paper condition",Scores!G$5:G$44,">=0"))-1) -> 0.2
A10: T4 | B10: =IF(Tasks!$G$5="No","",Tasks!E5&"") -> Gate | C10: =IF(Tasks!$G$5="No","",Tasks!D5&"") -> Model | D10: =IF(Tasks!$G$5="No","",COUNTIFS(Scores!$B$5:$B$44,1,Scores!$C$5:$C$44,"Tool condition",Scores!H$5:H$44,2)) -> 10 | E10: =IF(Tasks!$G$5="No","",COUNTIFS(Scores!$B$5:$B$44,1,Scores!$C$5:$C$44,"Paper condition",Scores!H$5:H$44,2)) -> 6 | F10: =IF(Tasks!$G$5="No","",COUNTIFS(Scores!$B$5:$B$44,2,Scores!$C$5:$C$44,"Tool condition",Scores!H$5:H$44,2)) -> 6 | G10: =IF(Tasks!$G$5="No","",COUNTIFS(Scores!$B$5:$B$44,2,Scores!$C$5:$C$44,"Paper condition",Scores!H$5:H$44,2)) -> 4 | H10: =IF(Tasks!$G$5="No","",IFERROR(AVERAGEIFS(Scores!H$5:H$44,Scores!$B$5:$B$44,1,Scores!$C$5:$C$44,"Tool condition"),"")) -> 2 | I10: =IF(Tasks!$G$5="No","",IFERROR(AVERAGEIFS(Scores!H$5:H$44,Scores!$B$5:$B$44,1,Scores!$C$5:$C$44,"Paper condition"),"")) -> 1.6 | J10: =IF(Tasks!$G$5="No","",IFERROR(AVERAGEIFS(Scores!H$5:H$44,Scores!$B$5:$B$44,2,Scores!$C$5:$C$44,"Tool condition"),"")) -> 1.6 | K10: =IF(Tasks!$G$5="No","",IFERROR(AVERAGEIFS(Scores!H$5:H$44,Scores!$B$5:$B$44,2,Scores!$C$5:$C$44,"Paper condition"),"")) -> 1.4 | L10: =IF(Tasks!$G$5="No","",IF(OR(COUNTIFS(Scores!$B$5:$B$44,1,Scores!$C$5:$C$44,"Tool condition",Scores!H$5:H$44,">=0")=0,COUNTIFS(Scores!$B$5:$B$44,1,Scores!$C$5:$C$44,"Paper condition",Scores!H$5:H$44,">=0")=0),"",SUM(Helper!Q$5:Q$44))) -> 70 | M10: =IF(L10="","",IF(SQRT(COUNTIFS(Scores!$B$5:$B$44,1,Scores!$C$5:$C$44,"Tool condition",Scores!H$5:H$44,">=0")*COUNTIFS(Scores!$B$5:$B$44,1,Scores!$C$5:$C$44,"Paper condition",Scores!H$5:H$44,">=0")/12*(((COUNTIFS(Scores!$B$5:$B$44,1,Scores!$C$5:$C$44,"Tool condition",Scores!H$5:H$44,">=0")+COUNTIFS(Scores!$B$5:$B$44,1,Scores!$C$5:$C$44,"Paper condition",Scores!H$5:H$44,">=0"))+1)-SUM(Helper!R$5:R$44)/((COUNTIFS(Scores!$B$5:$B$44,1,Scores!$C$5:$C$44,"Tool condition",Scores!H$5:H$44,">=0")+COUNTIFS(Scores!$B$5:$B$44,1,Scores!$C$5:$C$44,"Paper condition",Scores!H$5:H$44,">=0"))*((COUNTIFS(Scores!$B$5:$B$44,1,Scores!$C$5:$C$44,"Tool condition",Scores!H$5:H$44,">=0")+COUNTIFS(Scores!$B$5:$B$44,1,Scores!$C$5:$C$44,"Paper condition",Scores!H$5:H$44,">=0"))-1))))=0,1,MIN(1,2*(1-NORMSDIST((ABS(L10-COUNTIFS(Scores!$B$5:$B$44,1,Scores!$C$5:$C$44,"Tool condition",Scores!H$5:H$44,">=0")*COUNTIFS(Scores!$B$5:$B$44,1,Scores!$C$5:$C$44,"Paper condition",Scores!H$5:H$44,">=0")/2)-0.5)/SQRT(COUNTIFS(Scores!$B$5:$B$44,1,Scores!$C$5:$C$44,"Tool condition",Scores!H$5:H$44,">=0")*COUNTIFS(Scores!$B$5:$B$44,1,Scores!$C$5:$C$44,"Paper condition",Scores!H$5:H$44,">=0")/12*(((COUNTIFS(Scores!$B$5:$B$44,1,Scores!$C$5:$C$44,"Tool condition",Scores!H$5:H$44,">=0")+COUNTIFS(Scores!$B$5:$B$44,1,Scores!$C$5:$C$44,"Paper condition",Scores!H$5:H$44,">=0"))+1)-SUM(Helper!R$5:R$44)/((COUNTIFS(Scores!$B$5:$B$44,1,Scores!$C$5:$C$44,"Tool condition",Scores!H$5:H$44,">=0")+COUNTIFS(Scores!$B$5:$B$44,1,Scores!$C$5:$C$44,"Paper condition",Scores!H$5:H$44,">=0"))*((COUNTIFS(Scores!$B$5:$B$44,1,Scores!$C$5:$C$44,"Tool condition",Scores!H$5:H$44,">=0")+COUNTIFS(Scores!$B$5:$B$44,1,Scores!$C$5:$C$44,"Paper condition",Scores!H$5:H$44,">=0"))-1))))))))) -> 0.033589681 | N10: =IF(M10="","",INDEX(Helper!$D$100:$D$111,RANK(M10,Analysis!$M$7:$M$18,1)+COUNTIF(Analysis!$M$7:$M$18,M10)-1)) -> 0.20153808 | O10: =IF(L10="","",2*L10/(COUNTIFS(Scores!$B$5:$B$44,1,Scores!$C$5:$C$44,"Tool condition",Scores!H$5:H$44,">=0")*COUNTIFS(Scores!$B$5:$B$44,1,Scores!$C$5:$C$44,"Paper condition",Scores!H$5:H$44,">=0"))-1) -> 0.4 | P10: =IF(Tasks!$G$5="No","",IF(OR(COUNTIFS(Scores!$B$5:$B$44,2,Scores!$C$5:$C$44,"Tool condition",Scores!H$5:H$44,">=0")=0,COUNTIFS(Scores!$B$5:$B$44,2,Scores!$C$5:$C$44,"Paper condition",Scores!H$5:H$44,">=0")=0),"",SUM(Helper!S$5:S$44))) -> 60 | Q10: =IF(P10="","",IF(SQRT(COUNTIFS(Scores!$B$5:$B$44,2,Scores!$C$5:$C$44,"Tool condition",Scores!H$5:H$44,">=0")*COUNTIFS(Scores!$B$5:$B$44,2,Scores!$C$5:$C$44,"Paper condition",Scores!H$5:H$44,">=0")/12*(((COUNTIFS(Scores!$B$5:$B$44,2,Scores!$C$5:$C$44,"Tool condition",Scores!H$5:H$44,">=0")+COUNTIFS(Scores!$B$5:$B$44,2,Scores!$C$5:$C$44,"Paper condition",Scores!H$5:H$44,">=0"))+1)-SUM(Helper!T$5:T$44)/((COUNTIFS(Scores!$B$5:$B$44,2,Scores!$C$5:$C$44,"Tool condition",Scores!H$5:H$44,">=0")+COUNTIFS(Scores!$B$5:$B$44,2,Scores!$C$5:$C$44,"Paper condition",Scores!H$5:H$44,">=0"))*((COUNTIFS(Scores!$B$5:$B$44,2,Scores!$C$5:$C$44,"Tool condition",Scores!H$5:H$44,">=0")+COUNTIFS(Scores!$B$5:$B$44,2,Scores!$C$5:$C$44,"Paper condition",Scores!H$5:H$44,">=0"))-1))))=0,1,MIN(1,2*(1-NORMSDIST((ABS(P10-COUNTIFS(Scores!$B$5:$B$44,2,Scores!$C$5:$C$44,"Tool condition",Scores!H$5:H$44,">=0")*COUNTIFS(Scores!$B$5:$B$44,2,Scores!$C$5:$C$44,"Paper condition",Scores!H$5:H$44,">=0")/2)-0.5)/SQRT(COUNTIFS(Scores!$B$5:$B$44,2,Scores!$C$5:$C$44,"Tool condition",Scores!H$5:H$44,">=0")*COUNTIFS(Scores!$B$5:$B$44,2,Scores!$C$5:$C$44,"Paper condition",Scores!H$5:H$44,">=0")/12*(((COUNTIFS(Scores!$B$5:$B$44,2,Scores!$C$5:$C$44,"Tool condition",Scores!H$5:H$44,">=0")+COUNTIFS(Scores!$B$5:$B$44,2,Scores!$C$5:$C$44,"Paper condition",Scores!H$5:H$44,">=0"))+1)-SUM(Helper!T$5:T$44)/((COUNTIFS(Scores!$B$5:$B$44,2,Scores!$C$5:$C$44,"Tool condition",Scores!H$5:H$44,">=0")+COUNTIFS(Scores!$B$5:$B$44,2,Scores!$C$5:$C$44,"Paper condition",Scores!H$5:H$44,">=0"))*((COUNTIFS(Scores!$B$5:$B$44,2,Scores!$C$5:$C$44,"Tool condition",Scores!H$5:H$44,">=0")+COUNTIFS(Scores!$B$5:$B$44,2,Scores!$C$5:$C$44,"Paper condition",Scores!H$5:H$44,">=0"))-1))))))))) -> 0.40756245 | R10: =IF(Q10="","",INDEX(Helper!$H$100:$H$111,RANK(Q10,Analysis!$Q$7:$Q$18,1)+COUNTIF(Analysis!$Q$7:$Q$18,Q10)-1)) -> 1 | S10: =IF(P10="","",2*P10/(COUNTIFS(Scores!$B$5:$B$44,2,Scores!$C$5:$C$44,"Tool condition",Scores!H$5:H$44,">=0")*COUNTIFS(Scores!$B$5:$B$44,2,Scores!$C$5:$C$44,"Paper condition",Scores!H$5:H$44,">=0"))-1) -> 0.2
A11: T5 | B11: =IF(Tasks!$G$6="No","",Tasks!E6&"") -> Gate | C11: =IF(Tasks!$G$6="No","",Tasks!D6&"") -> Derivation | D11: =IF(Tasks!$G$6="No","",COUNTIFS(Scores!$B$5:$B$44,1,Scores!$C$5:$C$44,"Tool condition",Scores!I$5:I$44,2)) -> 10 | E11: =IF(Tasks!$G$6="No","",COUNTIFS(Scores!$B$5:$B$44,1,Scores!$C$5:$C$44,"Paper condition",Scores!I$5:I$44,2)) -> 4 | F11: =IF(Tasks!$G$6="No","",COUNTIFS(Scores!$B$5:$B$44,2,Scores!$C$5:$C$44,"Tool condition",Scores!I$5:I$44,2)) -> 7 | G11: =IF(Tasks!$G$6="No","",COUNTIFS(Scores!$B$5:$B$44,2,Scores!$C$5:$C$44,"Paper condition",Scores!I$5:I$44,2)) -> 3 | H11: =IF(Tasks!$G$6="No","",IFERROR(AVERAGEIFS(Scores!I$5:I$44,Scores!$B$5:$B$44,1,Scores!$C$5:$C$44,"Tool condition"),"")) -> 2 | I11: =IF(Tasks!$G$6="No","",IFERROR(AVERAGEIFS(Scores!I$5:I$44,Scores!$B$5:$B$44,1,Scores!$C$5:$C$44,"Paper condition"),"")) -> 1.2 | J11: =IF(Tasks!$G$6="No","",IFERROR(AVERAGEIFS(Scores!I$5:I$44,Scores!$B$5:$B$44,2,Scores!$C$5:$C$44,"Tool condition"),"")) -> 1.7 | K11: =IF(Tasks!$G$6="No","",IFERROR(AVERAGEIFS(Scores!I$5:I$44,Scores!$B$5:$B$44,2,Scores!$C$5:$C$44,"Paper condition"),"")) -> 1.2 | L11: =IF(Tasks!$G$6="No","",IF(OR(COUNTIFS(Scores!$B$5:$B$44,1,Scores!$C$5:$C$44,"Tool condition",Scores!I$5:I$44,">=0")=0,COUNTIFS(Scores!$B$5:$B$44,1,Scores!$C$5:$C$44,"Paper condition",Scores!I$5:I$44,">=0")=0),"",SUM(Helper!V$5:V$44))) -> 80 | M11: =IF(L11="","",IF(SQRT(COUNTIFS(Scores!$B$5:$B$44,1,Scores!$C$5:$C$44,"Tool condition",Scores!I$5:I$44,">=0")*COUNTIFS(Scores!$B$5:$B$44,1,Scores!$C$5:$C$44,"Paper condition",Scores!I$5:I$44,">=0")/12*(((COUNTIFS(Scores!$B$5:$B$44,1,Scores!$C$5:$C$44,"Tool condition",Scores!I$5:I$44,">=0")+COUNTIFS(Scores!$B$5:$B$44,1,Scores!$C$5:$C$44,"Paper condition",Scores!I$5:I$44,">=0"))+1)-SUM(Helper!W$5:W$44)/((COUNTIFS(Scores!$B$5:$B$44,1,Scores!$C$5:$C$44,"Tool condition",Scores!I$5:I$44,">=0")+COUNTIFS(Scores!$B$5:$B$44,1,Scores!$C$5:$C$44,"Paper condition",Scores!I$5:I$44,">=0"))*((COUNTIFS(Scores!$B$5:$B$44,1,Scores!$C$5:$C$44,"Tool condition",Scores!I$5:I$44,">=0")+COUNTIFS(Scores!$B$5:$B$44,1,Scores!$C$5:$C$44,"Paper condition",Scores!I$5:I$44,">=0"))-1))))=0,1,MIN(1,2*(1-NORMSDIST((ABS(L11-COUNTIFS(Scores!$B$5:$B$44,1,Scores!$C$5:$C$44,"Tool condition",Scores!I$5:I$44,">=0")*COUNTIFS(Scores!$B$5:$B$44,1,Scores!$C$5:$C$44,"Paper condition",Scores!I$5:I$44,">=0")/2)-0.5)/SQRT(COUNTIFS(Scores!$B$5:$B$44,1,Scores!$C$5:$C$44,"Tool condition",Scores!I$5:I$44,">=0")*COUNTIFS(Scores!$B$5:$B$44,1,Scores!$C$5:$C$44,"Paper condition",Scores!I$5:I$44,">=0")/12*(((COUNTIFS(Scores!$B$5:$B$44,1,Scores!$C$5:$C$44,"Tool condition",Scores!I$5:I$44,">=0")+COUNTIFS(Scores!$B$5:$B$44,1,Scores!$C$5:$C$44,"Paper condition",Scores!I$5:I$44,">=0"))+1)-SUM(Helper!W$5:W$44)/((COUNTIFS(Scores!$B$5:$B$44,1,Scores!$C$5:$C$44,"Tool condition",Scores!I$5:I$44,">=0")+COUNTIFS(Scores!$B$5:$B$44,1,Scores!$C$5:$C$44,"Paper condition",Scores!I$5:I$44,">=0"))*((COUNTIFS(Scores!$B$5:$B$44,1,Scores!$C$5:$C$44,"Tool condition",Scores!I$5:I$44,">=0")+COUNTIFS(Scores!$B$5:$B$44,1,Scores!$C$5:$C$44,"Paper condition",Scores!I$5:I$44,">=0"))-1))))))))) -> 0.0056615918 | N11: =IF(M11="","",INDEX(Helper!$D$100:$D$111,RANK(M11,Analysis!$M$7:$M$18,1)+COUNTIF(Analysis!$M$7:$M$18,M11)-1)) -> 0.059558292 | O11: =IF(L11="","",2*L11/(COUNTIFS(Scores!$B$5:$B$44,1,Scores!$C$5:$C$44,"Tool condition",Scores!I$5:I$44,">=0")*COUNTIFS(Scores!$B$5:$B$44,1,Scores!$C$5:$C$44,"Paper condition",Scores!I$5:I$44,">=0"))-1) -> 0.6 | P11: =IF(Tasks!$G$6="No","",IF(OR(COUNTIFS(Scores!$B$5:$B$44,2,Scores!$C$5:$C$44,"Tool condition",Scores!I$5:I$44,">=0")=0,COUNTIFS(Scores!$B$5:$B$44,2,Scores!$C$5:$C$44,"Paper condition",Scores!I$5:I$44,">=0")=0),"",SUM(Helper!X$5:X$44))) -> 71.5 | Q11: =IF(P11="","",IF(SQRT(COUNTIFS(Scores!$B$5:$B$44,2,Scores!$C$5:$C$44,"Tool condition",Scores!I$5:I$44,">=0")*COUNTIFS(Scores!$B$5:$B$44,2,Scores!$C$5:$C$44,"Paper condition",Scores!I$5:I$44,">=0")/12*(((COUNTIFS(Scores!$B$5:$B$44,2,Scores!$C$5:$C$44,"Tool condition",Scores!I$5:I$44,">=0")+COUNTIFS(Scores!$B$5:$B$44,2,Scores!$C$5:$C$44,"Paper condition",Scores!I$5:I$44,">=0"))+1)-SUM(Helper!Y$5:Y$44)/((COUNTIFS(Scores!$B$5:$B$44,2,Scores!$C$5:$C$44,"Tool condition",Scores!I$5:I$44,">=0")+COUNTIFS(Scores!$B$5:$B$44,2,Scores!$C$5:$C$44,"Paper condition",Scores!I$5:I$44,">=0"))*((COUNTIFS(Scores!$B$5:$B$44,2,Scores!$C$5:$C$44,"Tool condition",Scores!I$5:I$44,">=0")+COUNTIFS(Scores!$B$5:$B$44,2,Scores!$C$5:$C$44,"Paper condition",Scores!I$5:I$44,">=0"))-1))))=0,1,MIN(1,2*(1-NORMSDIST((ABS(P11-COUNTIFS(Scores!$B$5:$B$44,2,Scores!$C$5:$C$44,"Tool condition",Scores!I$5:I$44,">=0")*COUNTIFS(Scores!$B$5:$B$44,2,Scores!$C$5:$C$44,"Paper condition",Scores!I$5:I$44,">=0")/2)-0.5)/SQRT(COUNTIFS(Scores!$B$5:$B$44,2,Scores!$C$5:$C$44,"Tool condition",Scores!I$5:I$44,">=0")*COUNTIFS(Scores!$B$5:$B$44,2,Scores!$C$5:$C$44,"Paper condition",Scores!I$5:I$44,">=0")/12*(((COUNTIFS(Scores!$B$5:$B$44,2,Scores!$C$5:$C$44,"Tool condition",Scores!I$5:I$44,">=0")+COUNTIFS(Scores!$B$5:$B$44,2,Scores!$C$5:$C$44,"Paper condition",Scores!I$5:I$44,">=0"))+1)-SUM(Helper!Y$5:Y$44)/((COUNTIFS(Scores!$B$5:$B$44,2,Scores!$C$5:$C$44,"Tool condition",Scores!I$5:I$44,">=0")+COUNTIFS(Scores!$B$5:$B$44,2,Scores!$C$5:$C$44,"Paper condition",Scores!I$5:I$44,">=0"))*((COUNTIFS(Scores!$B$5:$B$44,2,Scores!$C$5:$C$44,"Tool condition",Scores!I$5:I$44,">=0")+COUNTIFS(Scores!$B$5:$B$44,2,Scores!$C$5:$C$44,"Paper condition",Scores!I$5:I$44,">=0"))-1))))))))) -> 0.073311588 | R11: =IF(Q11="","",INDEX(Helper!$H$100:$H$111,RANK(Q11,Analysis!$Q$7:$Q$18,1)+COUNTIF(Analysis!$Q$7:$Q$18,Q11)-1)) -> 0.87973906 | S11: =IF(P11="","",2*P11/(COUNTIFS(Scores!$B$5:$B$44,2,Scores!$C$5:$C$44,"Tool condition",Scores!I$5:I$44,">=0")*COUNTIFS(Scores!$B$5:$B$44,2,Scores!$C$5:$C$44,"Paper condition",Scores!I$5:I$44,">=0"))-1) -> 0.43
A12: T6 | B12: =IF(Tasks!$G$7="No","",Tasks!E7&"") -> Gate | C12: =IF(Tasks!$G$7="No","",Tasks!D7&"") -> Code | D12: =IF(Tasks!$G$7="No","",COUNTIFS(Scores!$B$5:$B$44,1,Scores!$C$5:$C$44,"Tool condition",Scores!J$5:J$44,2)) -> 10 | E12: =IF(Tasks!$G$7="No","",COUNTIFS(Scores!$B$5:$B$44,1,Scores!$C$5:$C$44,"Paper condition",Scores!J$5:J$44,2)) -> 5 | F12: =IF(Tasks!$G$7="No","",COUNTIFS(Scores!$B$5:$B$44,2,Scores!$C$5:$C$44,"Tool condition",Scores!J$5:J$44,2)) -> 6 | G12: =IF(Tasks!$G$7="No","",COUNTIFS(Scores!$B$5:$B$44,2,Scores!$C$5:$C$44,"Paper condition",Scores!J$5:J$44,2)) -> 5 | H12: =IF(Tasks!$G$7="No","",IFERROR(AVERAGEIFS(Scores!J$5:J$44,Scores!$B$5:$B$44,1,Scores!$C$5:$C$44,"Tool condition"),"")) -> 2 | I12: =IF(Tasks!$G$7="No","",IFERROR(AVERAGEIFS(Scores!J$5:J$44,Scores!$B$5:$B$44,1,Scores!$C$5:$C$44,"Paper condition"),"")) -> 1.4 | J12: =IF(Tasks!$G$7="No","",IFERROR(AVERAGEIFS(Scores!J$5:J$44,Scores!$B$5:$B$44,2,Scores!$C$5:$C$44,"Tool condition"),"")) -> 1.6 | K12: =IF(Tasks!$G$7="No","",IFERROR(AVERAGEIFS(Scores!J$5:J$44,Scores!$B$5:$B$44,2,Scores!$C$5:$C$44,"Paper condition"),"")) -> 1.5 | L12: =IF(Tasks!$G$7="No","",IF(OR(COUNTIFS(Scores!$B$5:$B$44,1,Scores!$C$5:$C$44,"Tool condition",Scores!J$5:J$44,">=0")=0,COUNTIFS(Scores!$B$5:$B$44,1,Scores!$C$5:$C$44,"Paper condition",Scores!J$5:J$44,">=0")=0),"",SUM(Helper!AA$5:AA$44))) -> 75 | M12: =IF(L12="","",IF(SQRT(COUNTIFS(Scores!$B$5:$B$44,1,Scores!$C$5:$C$44,"Tool condition",Scores!J$5:J$44,">=0")*COUNTIFS(Scores!$B$5:$B$44,1,Scores!$C$5:$C$44,"Paper condition",Scores!J$5:J$44,">=0")/12*(((COUNTIFS(Scores!$B$5:$B$44,1,Scores!$C$5:$C$44,"Tool condition",Scores!J$5:J$44,">=0")+COUNTIFS(Scores!$B$5:$B$44,1,Scores!$C$5:$C$44,"Paper condition",Scores!J$5:J$44,">=0"))+1)-SUM(Helper!AB$5:AB$44)/((COUNTIFS(Scores!$B$5:$B$44,1,Scores!$C$5:$C$44,"Tool condition",Scores!J$5:J$44,">=0")+COUNTIFS(Scores!$B$5:$B$44,1,Scores!$C$5:$C$44,"Paper condition",Scores!J$5:J$44,">=0"))*((COUNTIFS(Scores!$B$5:$B$44,1,Scores!$C$5:$C$44,"Tool condition",Scores!J$5:J$44,">=0")+COUNTIFS(Scores!$B$5:$B$44,1,Scores!$C$5:$C$44,"Paper condition",Scores!J$5:J$44,">=0"))-1))))=0,1,MIN(1,2*(1-NORMSDIST((ABS(L12-COUNTIFS(Scores!$B$5:$B$44,1,Scores!$C$5:$C$44,"Tool condition",Scores!J$5:J$44,">=0")*COUNTIFS(Scores!$B$5:$B$44,1,Scores!$C$5:$C$44,"Paper condition",Scores!J$5:J$44,">=0")/2)-0.5)/SQRT(COUNTIFS(Scores!$B$5:$B$44,1,Scores!$C$5:$C$44,"Tool condition",Scores!J$5:J$44,">=0")*COUNTIFS(Scores!$B$5:$B$44,1,Scores!$C$5:$C$44,"Paper condition",Scores!J$5:J$44,">=0")/12*(((COUNTIFS(Scores!$B$5:$B$44,1,Scores!$C$5:$C$44,"Tool condition",Scores!J$5:J$44,">=0")+COUNTIFS(Scores!$B$5:$B$44,1,Scores!$C$5:$C$44,"Paper condition",Scores!J$5:J$44,">=0"))+1)-SUM(Helper!AB$5:AB$44)/((COUNTIFS(Scores!$B$5:$B$44,1,Scores!$C$5:$C$44,"Tool condition",Scores!J$5:J$44,">=0")+COUNTIFS(Scores!$B$5:$B$44,1,Scores!$C$5:$C$44,"Paper condition",Scores!J$5:J$44,">=0"))*((COUNTIFS(Scores!$B$5:$B$44,1,Scores!$C$5:$C$44,"Tool condition",Scores!J$5:J$44,">=0")+COUNTIFS(Scores!$B$5:$B$44,1,Scores!$C$5:$C$44,"Paper condition",Scores!J$5:J$44,">=0"))-1))))))))) -> 0.014285621 | N12: =IF(M12="","",INDEX(Helper!$D$100:$D$111,RANK(M12,Analysis!$M$7:$M$18,1)+COUNTIF(Analysis!$M$7:$M$18,M12)-1)) -> 0.11428497 | O12: =IF(L12="","",2*L12/(COUNTIFS(Scores!$B$5:$B$44,1,Scores!$C$5:$C$44,"Tool condition",Scores!J$5:J$44,">=0")*COUNTIFS(Scores!$B$5:$B$44,1,Scores!$C$5:$C$44,"Paper condition",Scores!J$5:J$44,">=0"))-1) -> 0.5 | P12: =IF(Tasks!$G$7="No","",IF(OR(COUNTIFS(Scores!$B$5:$B$44,2,Scores!$C$5:$C$44,"Tool condition",Scores!J$5:J$44,">=0")=0,COUNTIFS(Scores!$B$5:$B$44,2,Scores!$C$5:$C$44,"Paper condition",Scores!J$5:J$44,">=0")=0),"",SUM(Helper!AC$5:AC$44))) -> 55 | Q12: =IF(P12="","",IF(SQRT(COUNTIFS(Scores!$B$5:$B$44,2,Scores!$C$5:$C$44,"Tool condition",Scores!J$5:J$44,">=0")*COUNTIFS(Scores!$B$5:$B$44,2,Scores!$C$5:$C$44,"Paper condition",Scores!J$5:J$44,">=0")/12*(((COUNTIFS(Scores!$B$5:$B$44,2,Scores!$C$5:$C$44,"Tool condition",Scores!J$5:J$44,">=0")+COUNTIFS(Scores!$B$5:$B$44,2,Scores!$C$5:$C$44,"Paper condition",Scores!J$5:J$44,">=0"))+1)-SUM(Helper!AD$5:AD$44)/((COUNTIFS(Scores!$B$5:$B$44,2,Scores!$C$5:$C$44,"Tool condition",Scores!J$5:J$44,">=0")+COUNTIFS(Scores!$B$5:$B$44,2,Scores!$C$5:$C$44,"Paper condition",Scores!J$5:J$44,">=0"))*((COUNTIFS(Scores!$B$5:$B$44,2,Scores!$C$5:$C$44,"Tool condition",Scores!J$5:J$44,">=0")+COUNTIFS(Scores!$B$5:$B$44,2,Scores!$C$5:$C$44,"Paper condition",Scores!J$5:J$44,">=0"))-1))))=0,1,MIN(1,2*(1-NORMSDIST((ABS(P12-COUNTIFS(Scores!$B$5:$B$44,2,Scores!$C$5:$C$44,"Tool condition",Scores!J$5:J$44,">=0")*COUNTIFS(Scores!$B$5:$B$44,2,Scores!$C$5:$C$44,"Paper condition",Scores!J$5:J$44,">=0")/2)-0.5)/SQRT(COUNTIFS(Scores!$B$5:$B$44,2,Scores!$C$5:$C$44,"Tool condition",Scores!J$5:J$44,">=0")*COUNTIFS(Scores!$B$5:$B$44,2,Scores!$C$5:$C$44,"Paper condition",Scores!J$5:J$44,">=0")/12*(((COUNTIFS(Scores!$B$5:$B$44,2,Scores!$C$5:$C$44,"Tool condition",Scores!J$5:J$44,">=0")+COUNTIFS(Scores!$B$5:$B$44,2,Scores!$C$5:$C$44,"Paper condition",Scores!J$5:J$44,">=0"))+1)-SUM(Helper!AD$5:AD$44)/((COUNTIFS(Scores!$B$5:$B$44,2,Scores!$C$5:$C$44,"Tool condition",Scores!J$5:J$44,">=0")+COUNTIFS(Scores!$B$5:$B$44,2,Scores!$C$5:$C$44,"Paper condition",Scores!J$5:J$44,">=0"))*((COUNTIFS(Scores!$B$5:$B$44,2,Scores!$C$5:$C$44,"Tool condition",Scores!J$5:J$44,">=0")+COUNTIFS(Scores!$B$5:$B$44,2,Scores!$C$5:$C$44,"Paper condition",Scores!J$5:J$44,">=0"))-1))))))))) -> 0.69337636 | R12: =IF(Q12="","",INDEX(Helper!$H$100:$H$111,RANK(Q12,Analysis!$Q$7:$Q$18,1)+COUNTIF(Analysis!$Q$7:$Q$18,Q12)-1)) -> 1 | S12: =IF(P12="","",2*P12/(COUNTIFS(Scores!$B$5:$B$44,2,Scores!$C$5:$C$44,"Tool condition",Scores!J$5:J$44,">=0")*COUNTIFS(Scores!$B$5:$B$44,2,Scores!$C$5:$C$44,"Paper condition",Scores!J$5:J$44,">=0"))-1) -> 0.1
A13: T7 | B13: =IF(Tasks!$G$8="No","",Tasks!E8&"") -> Block | C13: =IF(Tasks!$G$8="No","",Tasks!D8&"") -> Model | D13: =IF(Tasks!$G$8="No","",COUNTIFS(Scores!$B$5:$B$44,1,Scores!$C$5:$C$44,"Tool condition",Scores!K$5:K$44,2)) -> 10 | E13: =IF(Tasks!$G$8="No","",COUNTIFS(Scores!$B$5:$B$44,1,Scores!$C$5:$C$44,"Paper condition",Scores!K$5:K$44,2)) -> 6 | F13: =IF(Tasks!$G$8="No","",COUNTIFS(Scores!$B$5:$B$44,2,Scores!$C$5:$C$44,"Tool condition",Scores!K$5:K$44,2)) -> 6 | G13: =IF(Tasks!$G$8="No","",COUNTIFS(Scores!$B$5:$B$44,2,Scores!$C$5:$C$44,"Paper condition",Scores!K$5:K$44,2)) -> 3 | H13: =IF(Tasks!$G$8="No","",IFERROR(AVERAGEIFS(Scores!K$5:K$44,Scores!$B$5:$B$44,1,Scores!$C$5:$C$44,"Tool condition"),"")) -> 2 | I13: =IF(Tasks!$G$8="No","",IFERROR(AVERAGEIFS(Scores!K$5:K$44,Scores!$B$5:$B$44,1,Scores!$C$5:$C$44,"Paper condition"),"")) -> 1.6 | J13: =IF(Tasks!$G$8="No","",IFERROR(AVERAGEIFS(Scores!K$5:K$44,Scores!$B$5:$B$44,2,Scores!$C$5:$C$44,"Tool condition"),"")) -> 1.6 | K13: =IF(Tasks!$G$8="No","",IFERROR(AVERAGEIFS(Scores!K$5:K$44,Scores!$B$5:$B$44,2,Scores!$C$5:$C$44,"Paper condition"),"")) -> 1.3 | L13: =IF(Tasks!$G$8="No","",IF(OR(COUNTIFS(Scores!$B$5:$B$44,1,Scores!$C$5:$C$44,"Tool condition",Scores!K$5:K$44,">=0")=0,COUNTIFS(Scores!$B$5:$B$44,1,Scores!$C$5:$C$44,"Paper condition",Scores!K$5:K$44,">=0")=0),"",SUM(Helper!AF$5:AF$44))) -> 70 | M13: =IF(L13="","",IF(SQRT(COUNTIFS(Scores!$B$5:$B$44,1,Scores!$C$5:$C$44,"Tool condition",Scores!K$5:K$44,">=0")*COUNTIFS(Scores!$B$5:$B$44,1,Scores!$C$5:$C$44,"Paper condition",Scores!K$5:K$44,">=0")/12*(((COUNTIFS(Scores!$B$5:$B$44,1,Scores!$C$5:$C$44,"Tool condition",Scores!K$5:K$44,">=0")+COUNTIFS(Scores!$B$5:$B$44,1,Scores!$C$5:$C$44,"Paper condition",Scores!K$5:K$44,">=0"))+1)-SUM(Helper!AG$5:AG$44)/((COUNTIFS(Scores!$B$5:$B$44,1,Scores!$C$5:$C$44,"Tool condition",Scores!K$5:K$44,">=0")+COUNTIFS(Scores!$B$5:$B$44,1,Scores!$C$5:$C$44,"Paper condition",Scores!K$5:K$44,">=0"))*((COUNTIFS(Scores!$B$5:$B$44,1,Scores!$C$5:$C$44,"Tool condition",Scores!K$5:K$44,">=0")+COUNTIFS(Scores!$B$5:$B$44,1,Scores!$C$5:$C$44,"Paper condition",Scores!K$5:K$44,">=0"))-1))))=0,1,MIN(1,2*(1-NORMSDIST((ABS(L13-COUNTIFS(Scores!$B$5:$B$44,1,Scores!$C$5:$C$44,"Tool condition",Scores!K$5:K$44,">=0")*COUNTIFS(Scores!$B$5:$B$44,1,Scores!$C$5:$C$44,"Paper condition",Scores!K$5:K$44,">=0")/2)-0.5)/SQRT(COUNTIFS(Scores!$B$5:$B$44,1,Scores!$C$5:$C$44,"Tool condition",Scores!K$5:K$44,">=0")*COUNTIFS(Scores!$B$5:$B$44,1,Scores!$C$5:$C$44,"Paper condition",Scores!K$5:K$44,">=0")/12*(((COUNTIFS(Scores!$B$5:$B$44,1,Scores!$C$5:$C$44,"Tool condition",Scores!K$5:K$44,">=0")+COUNTIFS(Scores!$B$5:$B$44,1,Scores!$C$5:$C$44,"Paper condition",Scores!K$5:K$44,">=0"))+1)-SUM(Helper!AG$5:AG$44)/((COUNTIFS(Scores!$B$5:$B$44,1,Scores!$C$5:$C$44,"Tool condition",Scores!K$5:K$44,">=0")+COUNTIFS(Scores!$B$5:$B$44,1,Scores!$C$5:$C$44,"Paper condition",Scores!K$5:K$44,">=0"))*((COUNTIFS(Scores!$B$5:$B$44,1,Scores!$C$5:$C$44,"Tool condition",Scores!K$5:K$44,">=0")+COUNTIFS(Scores!$B$5:$B$44,1,Scores!$C$5:$C$44,"Paper condition",Scores!K$5:K$44,">=0"))-1))))))))) -> 0.033589681 | N13: =IF(M13="","",INDEX(Helper!$D$100:$D$111,RANK(M13,Analysis!$M$7:$M$18,1)+COUNTIF(Analysis!$M$7:$M$18,M13)-1)) -> 0.20153808 | O13: =IF(L13="","",2*L13/(COUNTIFS(Scores!$B$5:$B$44,1,Scores!$C$5:$C$44,"Tool condition",Scores!K$5:K$44,">=0")*COUNTIFS(Scores!$B$5:$B$44,1,Scores!$C$5:$C$44,"Paper condition",Scores!K$5:K$44,">=0"))-1) -> 0.4 | P13: =IF(Tasks!$G$8="No","",IF(OR(COUNTIFS(Scores!$B$5:$B$44,2,Scores!$C$5:$C$44,"Tool condition",Scores!K$5:K$44,">=0")=0,COUNTIFS(Scores!$B$5:$B$44,2,Scores!$C$5:$C$44,"Paper condition",Scores!K$5:K$44,">=0")=0),"",SUM(Helper!AH$5:AH$44))) -> 65 | Q13: =IF(P13="","",IF(SQRT(COUNTIFS(Scores!$B$5:$B$44,2,Scores!$C$5:$C$44,"Tool condition",Scores!K$5:K$44,">=0")*COUNTIFS(Scores!$B$5:$B$44,2,Scores!$C$5:$C$44,"Paper condition",Scores!K$5:K$44,">=0")/12*(((COUNTIFS(Scores!$B$5:$B$44,2,Scores!$C$5:$C$44,"Tool condition",Scores!K$5:K$44,">=0")+COUNTIFS(Scores!$B$5:$B$44,2,Scores!$C$5:$C$44,"Paper condition",Scores!K$5:K$44,">=0"))+1)-SUM(Helper!AI$5:AI$44)/((COUNTIFS(Scores!$B$5:$B$44,2,Scores!$C$5:$C$44,"Tool condition",Scores!K$5:K$44,">=0")+COUNTIFS(Scores!$B$5:$B$44,2,Scores!$C$5:$C$44,"Paper condition",Scores!K$5:K$44,">=0"))*((COUNTIFS(Scores!$B$5:$B$44,2,Scores!$C$5:$C$44,"Tool condition",Scores!K$5:K$44,">=0")+COUNTIFS(Scores!$B$5:$B$44,2,Scores!$C$5:$C$44,"Paper condition",Scores!K$5:K$44,">=0"))-1))))=0,1,MIN(1,2*(1-NORMSDIST((ABS(P13-COUNTIFS(Scores!$B$5:$B$44,2,Scores!$C$5:$C$44,"Tool condition",Scores!K$5:K$44,">=0")*COUNTIFS(Scores!$B$5:$B$44,2,Scores!$C$5:$C$44,"Paper condition",Scores!K$5:K$44,">=0")/2)-0.5)/SQRT(COUNTIFS(Scores!$B$5:$B$44,2,Scores!$C$5:$C$44,"Tool condition",Scores!K$5:K$44,">=0")*COUNTIFS(Scores!$B$5:$B$44,2,Scores!$C$5:$C$44,"Paper condition",Scores!K$5:K$44,">=0")/12*(((COUNTIFS(Scores!$B$5:$B$44,2,Scores!$C$5:$C$44,"Tool condition",Scores!K$5:K$44,">=0")+COUNTIFS(Scores!$B$5:$B$44,2,Scores!$C$5:$C$44,"Paper condition",Scores!K$5:K$44,">=0"))+1)-SUM(Helper!AI$5:AI$44)/((COUNTIFS(Scores!$B$5:$B$44,2,Scores!$C$5:$C$44,"Tool condition",Scores!K$5:K$44,">=0")+COUNTIFS(Scores!$B$5:$B$44,2,Scores!$C$5:$C$44,"Paper condition",Scores!K$5:K$44,">=0"))*((COUNTIFS(Scores!$B$5:$B$44,2,Scores!$C$5:$C$44,"Tool condition",Scores!K$5:K$44,">=0")+COUNTIFS(Scores!$B$5:$B$44,2,Scores!$C$5:$C$44,"Paper condition",Scores!K$5:K$44,">=0"))-1))))))))) -> 0.20392477 | R13: =IF(Q13="","",INDEX(Helper!$H$100:$H$111,RANK(Q13,Analysis!$Q$7:$Q$18,1)+COUNTIF(Analysis!$Q$7:$Q$18,Q13)-1)) -> 1 | S13: =IF(P13="","",2*P13/(COUNTIFS(Scores!$B$5:$B$44,2,Scores!$C$5:$C$44,"Tool condition",Scores!K$5:K$44,">=0")*COUNTIFS(Scores!$B$5:$B$44,2,Scores!$C$5:$C$44,"Paper condition",Scores!K$5:K$44,">=0"))-1) -> 0.3
A14: T8 | B14: =IF(Tasks!$G$9="No","",Tasks!E9&"") -> Block | C14: =IF(Tasks!$G$9="No","",Tasks!D9&"") -> Derivation | D14: =IF(Tasks!$G$9="No","",COUNTIFS(Scores!$B$5:$B$44,1,Scores!$C$5:$C$44,"Tool condition",Scores!L$5:L$44,2)) -> 10 | E14: =IF(Tasks!$G$9="No","",COUNTIFS(Scores!$B$5:$B$44,1,Scores!$C$5:$C$44,"Paper condition",Scores!L$5:L$44,2)) -> 7 | F14: =IF(Tasks!$G$9="No","",COUNTIFS(Scores!$B$5:$B$44,2,Scores!$C$5:$C$44,"Tool condition",Scores!L$5:L$44,2)) -> 5 | G14: =IF(Tasks!$G$9="No","",COUNTIFS(Scores!$B$5:$B$44,2,Scores!$C$5:$C$44,"Paper condition",Scores!L$5:L$44,2)) -> 5 | H14: =IF(Tasks!$G$9="No","",IFERROR(AVERAGEIFS(Scores!L$5:L$44,Scores!$B$5:$B$44,1,Scores!$C$5:$C$44,"Tool condition"),"")) -> 2 | I14: =IF(Tasks!$G$9="No","",IFERROR(AVERAGEIFS(Scores!L$5:L$44,Scores!$B$5:$B$44,1,Scores!$C$5:$C$44,"Paper condition"),"")) -> 1.7 | J14: =IF(Tasks!$G$9="No","",IFERROR(AVERAGEIFS(Scores!L$5:L$44,Scores!$B$5:$B$44,2,Scores!$C$5:$C$44,"Tool condition"),"")) -> 1.5 | K14: =IF(Tasks!$G$9="No","",IFERROR(AVERAGEIFS(Scores!L$5:L$44,Scores!$B$5:$B$44,2,Scores!$C$5:$C$44,"Paper condition"),"")) -> 1.5 | L14: =IF(Tasks!$G$9="No","",IF(OR(COUNTIFS(Scores!$B$5:$B$44,1,Scores!$C$5:$C$44,"Tool condition",Scores!L$5:L$44,">=0")=0,COUNTIFS(Scores!$B$5:$B$44,1,Scores!$C$5:$C$44,"Paper condition",Scores!L$5:L$44,">=0")=0),"",SUM(Helper!AK$5:AK$44))) -> 65 | M14: =IF(L14="","",IF(SQRT(COUNTIFS(Scores!$B$5:$B$44,1,Scores!$C$5:$C$44,"Tool condition",Scores!L$5:L$44,">=0")*COUNTIFS(Scores!$B$5:$B$44,1,Scores!$C$5:$C$44,"Paper condition",Scores!L$5:L$44,">=0")/12*(((COUNTIFS(Scores!$B$5:$B$44,1,Scores!$C$5:$C$44,"Tool condition",Scores!L$5:L$44,">=0")+COUNTIFS(Scores!$B$5:$B$44,1,Scores!$C$5:$C$44,"Paper condition",Scores!L$5:L$44,">=0"))+1)-SUM(Helper!AL$5:AL$44)/((COUNTIFS(Scores!$B$5:$B$44,1,Scores!$C$5:$C$44,"Tool condition",Scores!L$5:L$44,">=0")+COUNTIFS(Scores!$B$5:$B$44,1,Scores!$C$5:$C$44,"Paper condition",Scores!L$5:L$44,">=0"))*((COUNTIFS(Scores!$B$5:$B$44,1,Scores!$C$5:$C$44,"Tool condition",Scores!L$5:L$44,">=0")+COUNTIFS(Scores!$B$5:$B$44,1,Scores!$C$5:$C$44,"Paper condition",Scores!L$5:L$44,">=0"))-1))))=0,1,MIN(1,2*(1-NORMSDIST((ABS(L14-COUNTIFS(Scores!$B$5:$B$44,1,Scores!$C$5:$C$44,"Tool condition",Scores!L$5:L$44,">=0")*COUNTIFS(Scores!$B$5:$B$44,1,Scores!$C$5:$C$44,"Paper condition",Scores!L$5:L$44,">=0")/2)-0.5)/SQRT(COUNTIFS(Scores!$B$5:$B$44,1,Scores!$C$5:$C$44,"Tool condition",Scores!L$5:L$44,">=0")*COUNTIFS(Scores!$B$5:$B$44,1,Scores!$C$5:$C$44,"Paper condition",Scores!L$5:L$44,">=0")/12*(((COUNTIFS(Scores!$B$5:$B$44,1,Scores!$C$5:$C$44,"Tool condition",Scores!L$5:L$44,">=0")+COUNTIFS(Scores!$B$5:$B$44,1,Scores!$C$5:$C$44,"Paper condition",Scores!L$5:L$44,">=0"))+1)-SUM(Helper!AL$5:AL$44)/((COUNTIFS(Scores!$B$5:$B$44,1,Scores!$C$5:$C$44,"Tool condition",Scores!L$5:L$44,">=0")+COUNTIFS(Scores!$B$5:$B$44,1,Scores!$C$5:$C$44,"Paper condition",Scores!L$5:L$44,">=0"))*((COUNTIFS(Scores!$B$5:$B$44,1,Scores!$C$5:$C$44,"Tool condition",Scores!L$5:L$44,">=0")+COUNTIFS(Scores!$B$5:$B$44,1,Scores!$C$5:$C$44,"Paper condition",Scores!L$5:L$44,">=0"))-1))))))))) -> 0.076715977 | N14: =IF(M14="","",INDEX(Helper!$D$100:$D$111,RANK(M14,Analysis!$M$7:$M$18,1)+COUNTIF(Analysis!$M$7:$M$18,M14)-1)) -> 0.23014793 | O14: =IF(L14="","",2*L14/(COUNTIFS(Scores!$B$5:$B$44,1,Scores!$C$5:$C$44,"Tool condition",Scores!L$5:L$44,">=0")*COUNTIFS(Scores!$B$5:$B$44,1,Scores!$C$5:$C$44,"Paper condition",Scores!L$5:L$44,">=0"))-1) -> 0.3 | P14: =IF(Tasks!$G$9="No","",IF(OR(COUNTIFS(Scores!$B$5:$B$44,2,Scores!$C$5:$C$44,"Tool condition",Scores!L$5:L$44,">=0")=0,COUNTIFS(Scores!$B$5:$B$44,2,Scores!$C$5:$C$44,"Paper condition",Scores!L$5:L$44,">=0")=0),"",SUM(Helper!AM$5:AM$44))) -> 50 | Q14: =IF(P14="","",IF(SQRT(COUNTIFS(Scores!$B$5:$B$44,2,Scores!$C$5:$C$44,"Tool condition",Scores!L$5:L$44,">=0")*COUNTIFS(Scores!$B$5:$B$44,2,Scores!$C$5:$C$44,"Paper condition",Scores!L$5:L$44,">=0")/12*(((COUNTIFS(Scores!$B$5:$B$44,2,Scores!$C$5:$C$44,"Tool condition",Scores!L$5:L$44,">=0")+COUNTIFS(Scores!$B$5:$B$44,2,Scores!$C$5:$C$44,"Paper condition",Scores!L$5:L$44,">=0"))+1)-SUM(Helper!AN$5:AN$44)/((COUNTIFS(Scores!$B$5:$B$44,2,Scores!$C$5:$C$44,"Tool condition",Scores!L$5:L$44,">=0")+COUNTIFS(Scores!$B$5:$B$44,2,Scores!$C$5:$C$44,"Paper condition",Scores!L$5:L$44,">=0"))*((COUNTIFS(Scores!$B$5:$B$44,2,Scores!$C$5:$C$44,"Tool condition",Scores!L$5:L$44,">=0")+COUNTIFS(Scores!$B$5:$B$44,2,Scores!$C$5:$C$44,"Paper condition",Scores!L$5:L$44,">=0"))-1))))=0,1,MIN(1,2*(1-NORMSDIST((ABS(P14-COUNTIFS(Scores!$B$5:$B$44,2,Scores!$C$5:$C$44,"Tool condition",Scores!L$5:L$44,">=0")*COUNTIFS(Scores!$B$5:$B$44,2,Scores!$C$5:$C$44,"Paper condition",Scores!L$5:L$44,">=0")/2)-0.5)/SQRT(COUNTIFS(Scores!$B$5:$B$44,2,Scores!$C$5:$C$44,"Tool condition",Scores!L$5:L$44,">=0")*COUNTIFS(Scores!$B$5:$B$44,2,Scores!$C$5:$C$44,"Paper condition",Scores!L$5:L$44,">=0")/12*(((COUNTIFS(Scores!$B$5:$B$44,2,Scores!$C$5:$C$44,"Tool condition",Scores!L$5:L$44,">=0")+COUNTIFS(Scores!$B$5:$B$44,2,Scores!$C$5:$C$44,"Paper condition",Scores!L$5:L$44,">=0"))+1)-SUM(Helper!AN$5:AN$44)/((COUNTIFS(Scores!$B$5:$B$44,2,Scores!$C$5:$C$44,"Tool condition",Scores!L$5:L$44,">=0")+COUNTIFS(Scores!$B$5:$B$44,2,Scores!$C$5:$C$44,"Paper condition",Scores!L$5:L$44,">=0"))*((COUNTIFS(Scores!$B$5:$B$44,2,Scores!$C$5:$C$44,"Tool condition",Scores!L$5:L$44,">=0")+COUNTIFS(Scores!$B$5:$B$44,2,Scores!$C$5:$C$44,"Paper condition",Scores!L$5:L$44,">=0"))-1))))))))) -> 1 | R14: =IF(Q14="","",INDEX(Helper!$H$100:$H$111,RANK(Q14,Analysis!$Q$7:$Q$18,1)+COUNTIF(Analysis!$Q$7:$Q$18,Q14)-1)) -> 1 | S14: =IF(P14="","",2*P14/(COUNTIFS(Scores!$B$5:$B$44,2,Scores!$C$5:$C$44,"Tool condition",Scores!L$5:L$44,">=0")*COUNTIFS(Scores!$B$5:$B$44,2,Scores!$C$5:$C$44,"Paper condition",Scores!L$5:L$44,">=0"))-1) -> 0
A15: T9 | B15: =IF(Tasks!$G$10="No","",Tasks!E10&"") -> Block | C15: =IF(Tasks!$G$10="No","",Tasks!D10&"") -> Code | D15: =IF(Tasks!$G$10="No","",COUNTIFS(Scores!$B$5:$B$44,1,Scores!$C$5:$C$44,"Tool condition",Scores!M$5:M$44,2)) -> 10 | E15: =IF(Tasks!$G$10="No","",COUNTIFS(Scores!$B$5:$B$44,1,Scores!$C$5:$C$44,"Paper condition",Scores!M$5:M$44,2)) -> 7 | F15: =IF(Tasks!$G$10="No","",COUNTIFS(Scores!$B$5:$B$44,2,Scores!$C$5:$C$44,"Tool condition",Scores!M$5:M$44,2)) -> 4 | G15: =IF(Tasks!$G$10="No","",COUNTIFS(Scores!$B$5:$B$44,2,Scores!$C$5:$C$44,"Paper condition",Scores!M$5:M$44,2)) -> 4 | H15: =IF(Tasks!$G$10="No","",IFERROR(AVERAGEIFS(Scores!M$5:M$44,Scores!$B$5:$B$44,1,Scores!$C$5:$C$44,"Tool condition"),"")) -> 2 | I15: =IF(Tasks!$G$10="No","",IFERROR(AVERAGEIFS(Scores!M$5:M$44,Scores!$B$5:$B$44,1,Scores!$C$5:$C$44,"Paper condition"),"")) -> 1.7 | J15: =IF(Tasks!$G$10="No","",IFERROR(AVERAGEIFS(Scores!M$5:M$44,Scores!$B$5:$B$44,2,Scores!$C$5:$C$44,"Tool condition"),"")) -> 1.2 | K15: =IF(Tasks!$G$10="No","",IFERROR(AVERAGEIFS(Scores!M$5:M$44,Scores!$B$5:$B$44,2,Scores!$C$5:$C$44,"Paper condition"),"")) -> 1.3 | L15: =IF(Tasks!$G$10="No","",IF(OR(COUNTIFS(Scores!$B$5:$B$44,1,Scores!$C$5:$C$44,"Tool condition",Scores!M$5:M$44,">=0")=0,COUNTIFS(Scores!$B$5:$B$44,1,Scores!$C$5:$C$44,"Paper condition",Scores!M$5:M$44,">=0")=0),"",SUM(Helper!AP$5:AP$44))) -> 65 | M15: =IF(L15="","",IF(SQRT(COUNTIFS(Scores!$B$5:$B$44,1,Scores!$C$5:$C$44,"Tool condition",Scores!M$5:M$44,">=0")*COUNTIFS(Scores!$B$5:$B$44,1,Scores!$C$5:$C$44,"Paper condition",Scores!M$5:M$44,">=0")/12*(((COUNTIFS(Scores!$B$5:$B$44,1,Scores!$C$5:$C$44,"Tool condition",Scores!M$5:M$44,">=0")+COUNTIFS(Scores!$B$5:$B$44,1,Scores!$C$5:$C$44,"Paper condition",Scores!M$5:M$44,">=0"))+1)-SUM(Helper!AQ$5:AQ$44)/((COUNTIFS(Scores!$B$5:$B$44,1,Scores!$C$5:$C$44,"Tool condition",Scores!M$5:M$44,">=0")+COUNTIFS(Scores!$B$5:$B$44,1,Scores!$C$5:$C$44,"Paper condition",Scores!M$5:M$44,">=0"))*((COUNTIFS(Scores!$B$5:$B$44,1,Scores!$C$5:$C$44,"Tool condition",Scores!M$5:M$44,">=0")+COUNTIFS(Scores!$B$5:$B$44,1,Scores!$C$5:$C$44,"Paper condition",Scores!M$5:M$44,">=0"))-1))))=0,1,MIN(1,2*(1-NORMSDIST((ABS(L15-COUNTIFS(Scores!$B$5:$B$44,1,Scores!$C$5:$C$44,"Tool condition",Scores!M$5:M$44,">=0")*COUNTIFS(Scores!$B$5:$B$44,1,Scores!$C$5:$C$44,"Paper condition",Scores!M$5:M$44,">=0")/2)-0.5)/SQRT(COUNTIFS(Scores!$B$5:$B$44,1,Scores!$C$5:$C$44,"Tool condition",Scores!M$5:M$44,">=0")*COUNTIFS(Scores!$B$5:$B$44,1,Scores!$C$5:$C$44,"Paper condition",Scores!M$5:M$44,">=0")/12*(((COUNTIFS(Scores!$B$5:$B$44,1,Scores!$C$5:$C$44,"Tool condition",Scores!M$5:M$44,">=0")+COUNTIFS(Scores!$B$5:$B$44,1,Scores!$C$5:$C$44,"Paper condition",Scores!M$5:M$44,">=0"))+1)-SUM(Helper!AQ$5:AQ$44)/((COUNTIFS(Scores!$B$5:$B$44,1,Scores!$C$5:$C$44,"Tool condition",Scores!M$5:M$44,">=0")+COUNTIFS(Scores!$B$5:$B$44,1,Scores!$C$5:$C$44,"Paper condition",Scores!M$5:M$44,">=0"))*((COUNTIFS(Scores!$B$5:$B$44,1,Scores!$C$5:$C$44,"Tool condition",Scores!M$5:M$44,">=0")+COUNTIFS(Scores!$B$5:$B$44,1,Scores!$C$5:$C$44,"Paper condition",Scores!M$5:M$44,">=0"))-1))))))))) -> 0.076715977 | N15: =IF(M15="","",INDEX(Helper!$D$100:$D$111,RANK(M15,Analysis!$M$7:$M$18,1)+COUNTIF(Analysis!$M$7:$M$18,M15)-1)) -> 0.23014793 | O15: =IF(L15="","",2*L15/(COUNTIFS(Scores!$B$5:$B$44,1,Scores!$C$5:$C$44,"Tool condition",Scores!M$5:M$44,">=0")*COUNTIFS(Scores!$B$5:$B$44,1,Scores!$C$5:$C$44,"Paper condition",Scores!M$5:M$44,">=0"))-1) -> 0.3 | P15: =IF(Tasks!$G$10="No","",IF(OR(COUNTIFS(Scores!$B$5:$B$44,2,Scores!$C$5:$C$44,"Tool condition",Scores!M$5:M$44,">=0")=0,COUNTIFS(Scores!$B$5:$B$44,2,Scores!$C$5:$C$44,"Paper condition",Scores!M$5:M$44,">=0")=0),"",SUM(Helper!AR$5:AR$44))) -> 47 | Q15: =IF(P15="","",IF(SQRT(COUNTIFS(Scores!$B$5:$B$44,2,Scores!$C$5:$C$44,"Tool condition",Scores!M$5:M$44,">=0")*COUNTIFS(Scores!$B$5:$B$44,2,Scores!$C$5:$C$44,"Paper condition",Scores!M$5:M$44,">=0")/12*(((COUNTIFS(Scores!$B$5:$B$44,2,Scores!$C$5:$C$44,"Tool condition",Scores!M$5:M$44,">=0")+COUNTIFS(Scores!$B$5:$B$44,2,Scores!$C$5:$C$44,"Paper condition",Scores!M$5:M$44,">=0"))+1)-SUM(Helper!AS$5:AS$44)/((COUNTIFS(Scores!$B$5:$B$44,2,Scores!$C$5:$C$44,"Tool condition",Scores!M$5:M$44,">=0")+COUNTIFS(Scores!$B$5:$B$44,2,Scores!$C$5:$C$44,"Paper condition",Scores!M$5:M$44,">=0"))*((COUNTIFS(Scores!$B$5:$B$44,2,Scores!$C$5:$C$44,"Tool condition",Scores!M$5:M$44,">=0")+COUNTIFS(Scores!$B$5:$B$44,2,Scores!$C$5:$C$44,"Paper condition",Scores!M$5:M$44,">=0"))-1))))=0,1,MIN(1,2*(1-NORMSDIST((ABS(P15-COUNTIFS(Scores!$B$5:$B$44,2,Scores!$C$5:$C$44,"Tool condition",Scores!M$5:M$44,">=0")*COUNTIFS(Scores!$B$5:$B$44,2,Scores!$C$5:$C$44,"Paper condition",Scores!M$5:M$44,">=0")/2)-0.5)/SQRT(COUNTIFS(Scores!$B$5:$B$44,2,Scores!$C$5:$C$44,"Tool condition",Scores!M$5:M$44,">=0")*COUNTIFS(Scores!$B$5:$B$44,2,Scores!$C$5:$C$44,"Paper condition",Scores!M$5:M$44,">=0")/12*(((COUNTIFS(Scores!$B$5:$B$44,2,Scores!$C$5:$C$44,"Tool condition",Scores!M$5:M$44,">=0")+COUNTIFS(Scores!$B$5:$B$44,2,Scores!$C$5:$C$44,"Paper condition",Scores!M$5:M$44,">=0"))+1)-SUM(Helper!AS$5:AS$44)/((COUNTIFS(Scores!$B$5:$B$44,2,Scores!$C$5:$C$44,"Tool condition",Scores!M$5:M$44,">=0")+COUNTIFS(Scores!$B$5:$B$44,2,Scores!$C$5:$C$44,"Paper condition",Scores!M$5:M$44,">=0"))*((COUNTIFS(Scores!$B$5:$B$44,2,Scores!$C$5:$C$44,"Tool condition",Scores!M$5:M$44,">=0")+COUNTIFS(Scores!$B$5:$B$44,2,Scores!$C$5:$C$44,"Paper condition",Scores!M$5:M$44,">=0"))-1))))))))) -> 0.8369823 | R15: =IF(Q15="","",INDEX(Helper!$H$100:$H$111,RANK(Q15,Analysis!$Q$7:$Q$18,1)+COUNTIF(Analysis!$Q$7:$Q$18,Q15)-1)) -> 1 | S15: =IF(P15="","",2*P15/(COUNTIFS(Scores!$B$5:$B$44,2,Scores!$C$5:$C$44,"Tool condition",Scores!M$5:M$44,">=0")*COUNTIFS(Scores!$B$5:$B$44,2,Scores!$C$5:$C$44,"Paper condition",Scores!M$5:M$44,">=0"))-1) -> -0.06
A16: T10 | B16: =IF(Tasks!$G$11="No","",Tasks!E11&"") -> Block | C16: =IF(Tasks!$G$11="No","",Tasks!D11&"") -> Code | D16: =IF(Tasks!$G$11="No","",COUNTIFS(Scores!$B$5:$B$44,1,Scores!$C$5:$C$44,"Tool condition",Scores!N$5:N$44,2)) -> 10 | E16: =IF(Tasks!$G$11="No","",COUNTIFS(Scores!$B$5:$B$44,1,Scores!$C$5:$C$44,"Paper condition",Scores!N$5:N$44,2)) -> 4 | F16: =IF(Tasks!$G$11="No","",COUNTIFS(Scores!$B$5:$B$44,2,Scores!$C$5:$C$44,"Tool condition",Scores!N$5:N$44,2)) -> 3 | G16: =IF(Tasks!$G$11="No","",COUNTIFS(Scores!$B$5:$B$44,2,Scores!$C$5:$C$44,"Paper condition",Scores!N$5:N$44,2)) -> 3 | H16: =IF(Tasks!$G$11="No","",IFERROR(AVERAGEIFS(Scores!N$5:N$44,Scores!$B$5:$B$44,1,Scores!$C$5:$C$44,"Tool condition"),"")) -> 2 | I16: =IF(Tasks!$G$11="No","",IFERROR(AVERAGEIFS(Scores!N$5:N$44,Scores!$B$5:$B$44,1,Scores!$C$5:$C$44,"Paper condition"),"")) -> 1.2 | J16: =IF(Tasks!$G$11="No","",IFERROR(AVERAGEIFS(Scores!N$5:N$44,Scores!$B$5:$B$44,2,Scores!$C$5:$C$44,"Tool condition"),"")) -> 1 | K16: =IF(Tasks!$G$11="No","",IFERROR(AVERAGEIFS(Scores!N$5:N$44,Scores!$B$5:$B$44,2,Scores!$C$5:$C$44,"Paper condition"),"")) -> 1.1 | L16: =IF(Tasks!$G$11="No","",IF(OR(COUNTIFS(Scores!$B$5:$B$44,1,Scores!$C$5:$C$44,"Tool condition",Scores!N$5:N$44,">=0")=0,COUNTIFS(Scores!$B$5:$B$44,1,Scores!$C$5:$C$44,"Paper condition",Scores!N$5:N$44,">=0")=0),"",SUM(Helper!AU$5:AU$44))) -> 80 | M16: =IF(L16="","",IF(SQRT(COUNTIFS(Scores!$B$5:$B$44,1,Scores!$C$5:$C$44,"Tool condition",Scores!N$5:N$44,">=0")*COUNTIFS(Scores!$B$5:$B$44,1,Scores!$C$5:$C$44,"Paper condition",Scores!N$5:N$44,">=0")/12*(((COUNTIFS(Scores!$B$5:$B$44,1,Scores!$C$5:$C$44,"Tool condition",Scores!N$5:N$44,">=0")+COUNTIFS(Scores!$B$5:$B$44,1,Scores!$C$5:$C$44,"Paper condition",Scores!N$5:N$44,">=0"))+1)-SUM(Helper!AV$5:AV$44)/((COUNTIFS(Scores!$B$5:$B$44,1,Scores!$C$5:$C$44,"Tool condition",Scores!N$5:N$44,">=0")+COUNTIFS(Scores!$B$5:$B$44,1,Scores!$C$5:$C$44,"Paper condition",Scores!N$5:N$44,">=0"))*((COUNTIFS(Scores!$B$5:$B$44,1,Scores!$C$5:$C$44,"Tool condition",Scores!N$5:N$44,">=0")+COUNTIFS(Scores!$B$5:$B$44,1,Scores!$C$5:$C$44,"Paper condition",Scores!N$5:N$44,">=0"))-1))))=0,1,MIN(1,2*(1-NORMSDIST((ABS(L16-COUNTIFS(Scores!$B$5:$B$44,1,Scores!$C$5:$C$44,"Tool condition",Scores!N$5:N$44,">=0")*COUNTIFS(Scores!$B$5:$B$44,1,Scores!$C$5:$C$44,"Paper condition",Scores!N$5:N$44,">=0")/2)-0.5)/SQRT(COUNTIFS(Scores!$B$5:$B$44,1,Scores!$C$5:$C$44,"Tool condition",Scores!N$5:N$44,">=0")*COUNTIFS(Scores!$B$5:$B$44,1,Scores!$C$5:$C$44,"Paper condition",Scores!N$5:N$44,">=0")/12*(((COUNTIFS(Scores!$B$5:$B$44,1,Scores!$C$5:$C$44,"Tool condition",Scores!N$5:N$44,">=0")+COUNTIFS(Scores!$B$5:$B$44,1,Scores!$C$5:$C$44,"Paper condition",Scores!N$5:N$44,">=0"))+1)-SUM(Helper!AV$5:AV$44)/((COUNTIFS(Scores!$B$5:$B$44,1,Scores!$C$5:$C$44,"Tool condition",Scores!N$5:N$44,">=0")+COUNTIFS(Scores!$B$5:$B$44,1,Scores!$C$5:$C$44,"Paper condition",Scores!N$5:N$44,">=0"))*((COUNTIFS(Scores!$B$5:$B$44,1,Scores!$C$5:$C$44,"Tool condition",Scores!N$5:N$44,">=0")+COUNTIFS(Scores!$B$5:$B$44,1,Scores!$C$5:$C$44,"Paper condition",Scores!N$5:N$44,">=0"))-1))))))))) -> 0.0056615918 | N16: =IF(M16="","",INDEX(Helper!$D$100:$D$111,RANK(M16,Analysis!$M$7:$M$18,1)+COUNTIF(Analysis!$M$7:$M$18,M16)-1)) -> 0.059558292 | O16: =IF(L16="","",2*L16/(COUNTIFS(Scores!$B$5:$B$44,1,Scores!$C$5:$C$44,"Tool condition",Scores!N$5:N$44,">=0")*COUNTIFS(Scores!$B$5:$B$44,1,Scores!$C$5:$C$44,"Paper condition",Scores!N$5:N$44,">=0"))-1) -> 0.6 | P16: =IF(Tasks!$G$11="No","",IF(OR(COUNTIFS(Scores!$B$5:$B$44,2,Scores!$C$5:$C$44,"Tool condition",Scores!N$5:N$44,">=0")=0,COUNTIFS(Scores!$B$5:$B$44,2,Scores!$C$5:$C$44,"Paper condition",Scores!N$5:N$44,">=0")=0),"",SUM(Helper!AW$5:AW$44))) -> 46.5 | Q16: =IF(P16="","",IF(SQRT(COUNTIFS(Scores!$B$5:$B$44,2,Scores!$C$5:$C$44,"Tool condition",Scores!N$5:N$44,">=0")*COUNTIFS(Scores!$B$5:$B$44,2,Scores!$C$5:$C$44,"Paper condition",Scores!N$5:N$44,">=0")/12*(((COUNTIFS(Scores!$B$5:$B$44,2,Scores!$C$5:$C$44,"Tool condition",Scores!N$5:N$44,">=0")+COUNTIFS(Scores!$B$5:$B$44,2,Scores!$C$5:$C$44,"Paper condition",Scores!N$5:N$44,">=0"))+1)-SUM(Helper!AX$5:AX$44)/((COUNTIFS(Scores!$B$5:$B$44,2,Scores!$C$5:$C$44,"Tool condition",Scores!N$5:N$44,">=0")+COUNTIFS(Scores!$B$5:$B$44,2,Scores!$C$5:$C$44,"Paper condition",Scores!N$5:N$44,">=0"))*((COUNTIFS(Scores!$B$5:$B$44,2,Scores!$C$5:$C$44,"Tool condition",Scores!N$5:N$44,">=0")+COUNTIFS(Scores!$B$5:$B$44,2,Scores!$C$5:$C$44,"Paper condition",Scores!N$5:N$44,">=0"))-1))))=0,1,MIN(1,2*(1-NORMSDIST((ABS(P16-COUNTIFS(Scores!$B$5:$B$44,2,Scores!$C$5:$C$44,"Tool condition",Scores!N$5:N$44,">=0")*COUNTIFS(Scores!$B$5:$B$44,2,Scores!$C$5:$C$44,"Paper condition",Scores!N$5:N$44,">=0")/2)-0.5)/SQRT(COUNTIFS(Scores!$B$5:$B$44,2,Scores!$C$5:$C$44,"Tool condition",Scores!N$5:N$44,">=0")*COUNTIFS(Scores!$B$5:$B$44,2,Scores!$C$5:$C$44,"Paper condition",Scores!N$5:N$44,">=0")/12*(((COUNTIFS(Scores!$B$5:$B$44,2,Scores!$C$5:$C$44,"Tool condition",Scores!N$5:N$44,">=0")+COUNTIFS(Scores!$B$5:$B$44,2,Scores!$C$5:$C$44,"Paper condition",Scores!N$5:N$44,">=0"))+1)-SUM(Helper!AX$5:AX$44)/((COUNTIFS(Scores!$B$5:$B$44,2,Scores!$C$5:$C$44,"Tool condition",Scores!N$5:N$44,">=0")+COUNTIFS(Scores!$B$5:$B$44,2,Scores!$C$5:$C$44,"Paper condition",Scores!N$5:N$44,">=0"))*((COUNTIFS(Scores!$B$5:$B$44,2,Scores!$C$5:$C$44,"Tool condition",Scores!N$5:N$44,">=0")+COUNTIFS(Scores!$B$5:$B$44,2,Scores!$C$5:$C$44,"Paper condition",Scores!N$5:N$44,">=0"))-1))))))))) -> 0.8077318 | R16: =IF(Q16="","",INDEX(Helper!$H$100:$H$111,RANK(Q16,Analysis!$Q$7:$Q$18,1)+COUNTIF(Analysis!$Q$7:$Q$18,Q16)-1)) -> 1 | S16: =IF(P16="","",2*P16/(COUNTIFS(Scores!$B$5:$B$44,2,Scores!$C$5:$C$44,"Tool condition",Scores!N$5:N$44,">=0")*COUNTIFS(Scores!$B$5:$B$44,2,Scores!$C$5:$C$44,"Paper condition",Scores!N$5:N$44,">=0"))-1) -> -0.07
